[2024-11-18T17:27:41.533+0000] {taskinstance.py:1956} INFO - Dependencies all met for dep_context=non-requeueable deps ti=<TaskInstance: spotify_recommender_dag_v3.get_dataset manual__2024-11-18T17:27:40.616035+00:00 [queued]>
[2024-11-18T17:27:41.537+0000] {taskinstance.py:1956} INFO - Dependencies all met for dep_context=requeueable deps ti=<TaskInstance: spotify_recommender_dag_v3.get_dataset manual__2024-11-18T17:27:40.616035+00:00 [queued]>
[2024-11-18T17:27:41.538+0000] {taskinstance.py:2170} INFO - Starting attempt 1 of 2
[2024-11-18T17:27:41.545+0000] {taskinstance.py:2191} INFO - Executing <Task(_PythonVirtualenvDecoratedOperator): get_dataset> on 2024-11-18 17:27:40.616035+00:00
[2024-11-18T17:27:41.547+0000] {standard_task_runner.py:60} INFO - Started process 647 to run task
[2024-11-18T17:27:41.548+0000] {standard_task_runner.py:87} INFO - Running: ['***', 'tasks', 'run', 'spotify_recommender_dag_v3', 'get_dataset', 'manual__2024-11-18T17:27:40.616035+00:00', '--job-id', '28', '--raw', '--subdir', 'DAGS_FOLDER/music_process.py', '--cfg-path', '/tmp/tmpda16qfof']
[2024-11-18T17:27:41.549+0000] {standard_task_runner.py:88} INFO - Job 28: Subtask get_dataset
[2024-11-18T17:27:41.575+0000] {task_command.py:423} INFO - Running <TaskInstance: spotify_recommender_dag_v3.get_dataset manual__2024-11-18T17:27:40.616035+00:00 [running]> on host 98017b53a184
[2024-11-18T17:27:41.613+0000] {taskinstance.py:2480} INFO - Exporting env vars: AIRFLOW_CTX_DAG_OWNER='Mart√≠n Horn' AIRFLOW_CTX_DAG_ID='spotify_recommender_dag_v3' AIRFLOW_CTX_TASK_ID='get_dataset' AIRFLOW_CTX_EXECUTION_DATE='2024-11-18T17:27:40.616035+00:00' AIRFLOW_CTX_TRY_NUMBER='1' AIRFLOW_CTX_DAG_RUN_ID='manual__2024-11-18T17:27:40.616035+00:00'
[2024-11-18T17:27:41.614+0000] {process_utils.py:182} INFO - Executing cmd: /usr/local/bin/python -m virtualenv /tmp/venvx7yqdo8h --system-site-packages --python=python
[2024-11-18T17:27:41.618+0000] {process_utils.py:186} INFO - Output:
[2024-11-18T17:27:41.952+0000] {process_utils.py:190} INFO - created virtual environment CPython3.8.18.final.0-64 in 118ms
[2024-11-18T17:27:41.953+0000] {process_utils.py:190} INFO -   creator CPython3Posix(dest=/tmp/venvx7yqdo8h, clear=False, no_vcs_ignore=False, global=True)
[2024-11-18T17:27:41.953+0000] {process_utils.py:190} INFO -   seeder FromAppData(download=False, pip=bundle, setuptools=bundle, wheel=bundle, via=copy, app_data_dir=/home/***/.local/share/virtualenv)
[2024-11-18T17:27:41.953+0000] {process_utils.py:190} INFO -     added seed packages: pip==23.3.1, setuptools==69.0.2, wheel==0.42.0
[2024-11-18T17:27:41.953+0000] {process_utils.py:190} INFO -   activators BashActivator,CShellActivator,FishActivator,NushellActivator,PowerShellActivator,PythonActivator
[2024-11-18T17:27:41.970+0000] {process_utils.py:182} INFO - Executing cmd: /tmp/venvx7yqdo8h/bin/pip install -r /tmp/venvx7yqdo8h/requirements.txt
[2024-11-18T17:27:41.973+0000] {process_utils.py:186} INFO - Output:
[2024-11-18T17:27:42.889+0000] {process_utils.py:190} INFO - Collecting boto3==1.28.0 (from -r /tmp/venvx7yqdo8h/requirements.txt (line 1))
[2024-11-18T17:27:42.891+0000] {process_utils.py:190} INFO -   Using cached boto3-1.28.0-py3-none-any.whl.metadata (6.6 kB)
[2024-11-18T17:27:42.892+0000] {process_utils.py:190} INFO - Requirement already satisfied: pandas==2.0.3 in /home/***/.local/lib/python3.8/site-packages (from -r /tmp/venvx7yqdo8h/requirements.txt (line 2)) (2.0.3)
[2024-11-18T17:27:43.292+0000] {process_utils.py:190} INFO - Collecting botocore<1.32.0,>=1.31.0 (from boto3==1.28.0->-r /tmp/venvx7yqdo8h/requirements.txt (line 1))
[2024-11-18T17:27:43.294+0000] {process_utils.py:190} INFO -   Using cached botocore-1.31.85-py3-none-any.whl.metadata (6.1 kB)
[2024-11-18T17:27:43.295+0000] {process_utils.py:190} INFO - Requirement already satisfied: jmespath<2.0.0,>=0.7.1 in /home/***/.local/lib/python3.8/site-packages (from boto3==1.28.0->-r /tmp/venvx7yqdo8h/requirements.txt (line 1)) (0.10.0)
[2024-11-18T17:27:43.317+0000] {process_utils.py:190} INFO - Collecting s3transfer<0.7.0,>=0.6.0 (from boto3==1.28.0->-r /tmp/venvx7yqdo8h/requirements.txt (line 1))
[2024-11-18T17:27:43.318+0000] {process_utils.py:190} INFO -   Using cached s3transfer-0.6.2-py3-none-any.whl.metadata (1.8 kB)
[2024-11-18T17:27:43.372+0000] {process_utils.py:190} INFO - Requirement already satisfied: python-dateutil>=2.8.2 in /home/***/.local/lib/python3.8/site-packages (from pandas==2.0.3->-r /tmp/venvx7yqdo8h/requirements.txt (line 2)) (2.8.2)
[2024-11-18T17:27:43.372+0000] {process_utils.py:190} INFO - Requirement already satisfied: pytz>=2020.1 in /home/***/.local/lib/python3.8/site-packages (from pandas==2.0.3->-r /tmp/venvx7yqdo8h/requirements.txt (line 2)) (2023.3.post1)
[2024-11-18T17:27:43.373+0000] {process_utils.py:190} INFO - Requirement already satisfied: tzdata>=2022.1 in /home/***/.local/lib/python3.8/site-packages (from pandas==2.0.3->-r /tmp/venvx7yqdo8h/requirements.txt (line 2)) (2023.4)
[2024-11-18T17:27:43.373+0000] {process_utils.py:190} INFO - Requirement already satisfied: numpy>=1.20.3 in /home/***/.local/lib/python3.8/site-packages (from pandas==2.0.3->-r /tmp/venvx7yqdo8h/requirements.txt (line 2)) (1.24.4)
[2024-11-18T17:27:43.378+0000] {process_utils.py:190} INFO - Requirement already satisfied: urllib3<1.27,>=1.25.4 in /home/***/.local/lib/python3.8/site-packages (from botocore<1.32.0,>=1.31.0->boto3==1.28.0->-r /tmp/venvx7yqdo8h/requirements.txt (line 1)) (1.26.18)
[2024-11-18T17:27:43.381+0000] {process_utils.py:190} INFO - Requirement already satisfied: six>=1.5 in /home/***/.local/lib/python3.8/site-packages (from python-dateutil>=2.8.2->pandas==2.0.3->-r /tmp/venvx7yqdo8h/requirements.txt (line 2)) (1.16.0)
[2024-11-18T17:27:43.547+0000] {process_utils.py:190} INFO - Using cached boto3-1.28.0-py3-none-any.whl (135 kB)
[2024-11-18T17:27:43.548+0000] {process_utils.py:190} INFO - Using cached botocore-1.31.85-py3-none-any.whl (11.3 MB)
[2024-11-18T17:27:43.559+0000] {process_utils.py:190} INFO - Using cached s3transfer-0.6.2-py3-none-any.whl (79 kB)
[2024-11-18T17:27:45.342+0000] {process_utils.py:190} INFO - Installing collected packages: botocore, s3transfer, boto3
[2024-11-18T17:27:45.343+0000] {process_utils.py:190} INFO -   Attempting uninstall: botocore
[2024-11-18T17:27:45.343+0000] {process_utils.py:190} INFO -     Found existing installation: botocore 1.35.44
[2024-11-18T17:27:45.343+0000] {process_utils.py:190} INFO -     Not uninstalling botocore at /home/***/.local/lib/python3.8/site-packages, outside environment /tmp/venvx7yqdo8h
[2024-11-18T17:27:45.344+0000] {process_utils.py:190} INFO -     Can't uninstall 'botocore'. No files were found to uninstall.
[2024-11-18T17:27:45.745+0000] {process_utils.py:190} INFO -   Attempting uninstall: s3transfer
[2024-11-18T17:27:45.746+0000] {process_utils.py:190} INFO -     Found existing installation: s3transfer 0.10.3
[2024-11-18T17:27:45.747+0000] {process_utils.py:190} INFO -     Not uninstalling s3transfer at /home/***/.local/lib/python3.8/site-packages, outside environment /tmp/venvx7yqdo8h
[2024-11-18T17:27:45.748+0000] {process_utils.py:190} INFO -     Can't uninstall 's3transfer'. No files were found to uninstall.
[2024-11-18T17:27:45.769+0000] {process_utils.py:190} INFO -   Attempting uninstall: boto3
[2024-11-18T17:27:45.770+0000] {process_utils.py:190} INFO -     Found existing installation: boto3 1.35.44
[2024-11-18T17:27:45.770+0000] {process_utils.py:190} INFO -     Not uninstalling boto3 at /home/***/.local/lib/python3.8/site-packages, outside environment /tmp/venvx7yqdo8h
[2024-11-18T17:27:45.770+0000] {process_utils.py:190} INFO -     Can't uninstall 'boto3'. No files were found to uninstall.
[2024-11-18T17:27:45.800+0000] {process_utils.py:190} INFO - ERROR: pip's dependency resolver does not currently take into account all the packages that are installed. This behaviour is the source of the following dependency conflicts.
[2024-11-18T17:27:45.801+0000] {process_utils.py:190} INFO - aiobotocore 2.9.0 requires botocore<1.33.14,>=1.33.2, but you have botocore 1.31.85 which is incompatible.
[2024-11-18T17:27:45.801+0000] {process_utils.py:190} INFO - Successfully installed boto3-1.28.0 botocore-1.31.85 s3transfer-0.6.2
[2024-11-18T17:27:45.873+0000] {process_utils.py:190} INFO - 
[2024-11-18T17:27:45.874+0000] {process_utils.py:190} INFO - [notice] A new release of pip is available: 23.3.1 -> 24.3.1
[2024-11-18T17:27:45.874+0000] {process_utils.py:190} INFO - [notice] To update, run: python -m pip install --upgrade pip
[2024-11-18T17:27:45.989+0000] {process_utils.py:182} INFO - Executing cmd: /tmp/venvx7yqdo8h/bin/python /tmp/venv-calln3xmp0v_/script.py /tmp/venv-calln3xmp0v_/script.in /tmp/venv-calln3xmp0v_/script.out /tmp/venv-calln3xmp0v_/string_args.txt /tmp/venv-calln3xmp0v_/termination.log
[2024-11-18T17:27:45.993+0000] {process_utils.py:186} INFO - Output:
[2024-11-18T17:27:47.461+0000] {process_utils.py:190} INFO - Traceback (most recent call last):
[2024-11-18T17:27:47.462+0000] {process_utils.py:190} INFO -   File "/tmp/venv-calln3xmp0v_/script.py", line 47, in get_dataset
[2024-11-18T17:27:47.462+0000] {process_utils.py:190} INFO -     response = s3_client.get_object(Bucket="data", Key='spotify/spotify_songs.csv')
[2024-11-18T17:27:47.463+0000] {process_utils.py:190} INFO -   File "/tmp/venvx7yqdo8h/lib/python3.8/site-packages/botocore/client.py", line 535, in _api_call
[2024-11-18T17:27:47.463+0000] {process_utils.py:190} INFO -     return self._make_api_call(operation_name, kwargs)
[2024-11-18T17:27:47.464+0000] {process_utils.py:190} INFO -   File "/tmp/venvx7yqdo8h/lib/python3.8/site-packages/botocore/client.py", line 983, in _make_api_call
[2024-11-18T17:27:47.464+0000] {process_utils.py:190} INFO -     raise error_class(parsed_response, operation_name)
[2024-11-18T17:27:47.464+0000] {process_utils.py:190} INFO - botocore.errorfactory.NoSuchKey: An error occurred (NoSuchKey) when calling the GetObject operation: The specified key does not exist.
[2024-11-18T17:27:47.465+0000] {process_utils.py:190} INFO - 
[2024-11-18T17:27:47.465+0000] {process_utils.py:190} INFO - During handling of the above exception, another exception occurred:
[2024-11-18T17:27:47.465+0000] {process_utils.py:190} INFO - 
[2024-11-18T17:27:47.465+0000] {process_utils.py:190} INFO - Traceback (most recent call last):
[2024-11-18T17:27:47.465+0000] {process_utils.py:190} INFO -   File "/tmp/venv-calln3xmp0v_/script.py", line 57, in <module>
[2024-11-18T17:27:47.466+0000] {process_utils.py:190} INFO -     res = get_dataset(*arg_dict["args"], **arg_dict["kwargs"])
[2024-11-18T17:27:47.466+0000] {process_utils.py:190} INFO -   File "/tmp/venv-calln3xmp0v_/script.py", line 51, in get_dataset
[2024-11-18T17:27:47.466+0000] {process_utils.py:190} INFO -     df = pd.read_csv(url)
[2024-11-18T17:27:47.466+0000] {process_utils.py:190} INFO -   File "/home/***/.local/lib/python3.8/site-packages/pandas/io/parsers/readers.py", line 912, in read_csv
[2024-11-18T17:27:47.466+0000] {process_utils.py:190} INFO -     return _read(filepath_or_buffer, kwds)
[2024-11-18T17:27:47.467+0000] {process_utils.py:190} INFO -   File "/home/***/.local/lib/python3.8/site-packages/pandas/io/parsers/readers.py", line 577, in _read
[2024-11-18T17:27:47.468+0000] {process_utils.py:190} INFO -     parser = TextFileReader(filepath_or_buffer, **kwds)
[2024-11-18T17:27:47.468+0000] {process_utils.py:190} INFO -   File "/home/***/.local/lib/python3.8/site-packages/pandas/io/parsers/readers.py", line 1407, in __init__
[2024-11-18T17:27:47.468+0000] {process_utils.py:190} INFO -     self._engine = self._make_engine(f, self.engine)
[2024-11-18T17:27:47.469+0000] {process_utils.py:190} INFO -   File "/home/***/.local/lib/python3.8/site-packages/pandas/io/parsers/readers.py", line 1661, in _make_engine
[2024-11-18T17:27:47.469+0000] {process_utils.py:190} INFO -     self.handles = get_handle(
[2024-11-18T17:27:47.469+0000] {process_utils.py:190} INFO -   File "/home/***/.local/lib/python3.8/site-packages/pandas/io/common.py", line 716, in get_handle
[2024-11-18T17:27:47.469+0000] {process_utils.py:190} INFO -     ioargs = _get_filepath_or_buffer(
[2024-11-18T17:27:47.470+0000] {process_utils.py:190} INFO -   File "/home/***/.local/lib/python3.8/site-packages/pandas/io/common.py", line 368, in _get_filepath_or_buffer
[2024-11-18T17:27:47.470+0000] {process_utils.py:190} INFO -     with urlopen(req_info) as req:
[2024-11-18T17:27:47.470+0000] {process_utils.py:190} INFO -   File "/home/***/.local/lib/python3.8/site-packages/pandas/io/common.py", line 270, in urlopen
[2024-11-18T17:27:47.471+0000] {process_utils.py:190} INFO -     return urllib.request.urlopen(*args, **kwargs)
[2024-11-18T17:27:47.471+0000] {process_utils.py:190} INFO -   File "/usr/local/lib/python3.8/urllib/request.py", line 222, in urlopen
[2024-11-18T17:27:47.471+0000] {process_utils.py:190} INFO -     return opener.open(url, data, timeout)
[2024-11-18T17:27:47.471+0000] {process_utils.py:190} INFO -   File "/usr/local/lib/python3.8/urllib/request.py", line 531, in open
[2024-11-18T17:27:47.472+0000] {process_utils.py:190} INFO -     response = meth(req, response)
[2024-11-18T17:27:47.472+0000] {process_utils.py:190} INFO -   File "/usr/local/lib/python3.8/urllib/request.py", line 640, in http_response
[2024-11-18T17:27:47.472+0000] {process_utils.py:190} INFO -     response = self.parent.error(
[2024-11-18T17:27:47.473+0000] {process_utils.py:190} INFO -   File "/usr/local/lib/python3.8/urllib/request.py", line 569, in error
[2024-11-18T17:27:47.473+0000] {process_utils.py:190} INFO -     return self._call_chain(*args)
[2024-11-18T17:27:47.473+0000] {process_utils.py:190} INFO -   File "/usr/local/lib/python3.8/urllib/request.py", line 502, in _call_chain
[2024-11-18T17:27:47.474+0000] {process_utils.py:190} INFO -     result = func(*args)
[2024-11-18T17:27:47.474+0000] {process_utils.py:190} INFO -   File "/usr/local/lib/python3.8/urllib/request.py", line 649, in http_error_default
[2024-11-18T17:27:47.474+0000] {process_utils.py:190} INFO -     raise HTTPError(req.full_url, code, msg, hdrs, fp)
[2024-11-18T17:27:47.475+0000] {process_utils.py:190} INFO - urllib.error.HTTPError: HTTP Error 404: Not Found
[2024-11-18T17:27:47.651+0000] {taskinstance.py:2698} ERROR - Task failed with exception
Traceback (most recent call last):
  File "/home/airflow/.local/lib/python3.8/site-packages/airflow/models/taskinstance.py", line 433, in _execute_task
    result = execute_callable(context=context, **execute_callable_kwargs)
  File "/home/airflow/.local/lib/python3.8/site-packages/airflow/decorators/base.py", line 241, in execute
    return_value = super().execute(context)
  File "/home/airflow/.local/lib/python3.8/site-packages/airflow/operators/python.py", line 400, in execute
    return super().execute(context=serializable_context)
  File "/home/airflow/.local/lib/python3.8/site-packages/airflow/operators/python.py", line 199, in execute
    return_value = self.execute_callable()
  File "/home/airflow/.local/lib/python3.8/site-packages/airflow/operators/python.py", line 716, in execute_callable
    result = self._execute_python_callable_in_subprocess(python_path)
  File "/home/airflow/.local/lib/python3.8/site-packages/airflow/operators/python.py", line 471, in _execute_python_callable_in_subprocess
    raise AirflowException(error_msg) from None
airflow.exceptions.AirflowException: Process returned non-zero exit status 1.
HTTP Error 404: Not Found
[2024-11-18T17:27:47.653+0000] {taskinstance.py:1138} INFO - Marking task as UP_FOR_RETRY. dag_id=spotify_recommender_dag_v3, task_id=get_dataset, execution_date=20241118T172740, start_date=20241118T172741, end_date=20241118T172747
[2024-11-18T17:27:47.659+0000] {standard_task_runner.py:107} ERROR - Failed to execute job 28 for task get_dataset (Process returned non-zero exit status 1.
HTTP Error 404: Not Found; 647)
[2024-11-18T17:27:47.682+0000] {local_task_job_runner.py:234} INFO - Task exited with return code 1
[2024-11-18T17:27:47.694+0000] {taskinstance.py:3280} INFO - 0 downstream tasks scheduled from follow-on schedule check
