[2024-12-14T16:31:17.966+0000] {taskinstance.py:1956} INFO - Dependencies all met for dep_context=non-requeueable deps ti=<TaskInstance: spotify_recommender_dag_v3.get_dataset scheduled__2024-12-08T00:00:00+00:00 [queued]>
[2024-12-14T16:31:17.970+0000] {taskinstance.py:1956} INFO - Dependencies all met for dep_context=requeueable deps ti=<TaskInstance: spotify_recommender_dag_v3.get_dataset scheduled__2024-12-08T00:00:00+00:00 [queued]>
[2024-12-14T16:31:17.970+0000] {taskinstance.py:2170} INFO - Starting attempt 1 of 2
[2024-12-14T16:31:17.979+0000] {taskinstance.py:2191} INFO - Executing <Task(_PythonVirtualenvDecoratedOperator): get_dataset> on 2024-12-08 00:00:00+00:00
[2024-12-14T16:31:17.981+0000] {standard_task_runner.py:60} INFO - Started process 253 to run task
[2024-12-14T16:31:17.983+0000] {standard_task_runner.py:87} INFO - Running: ['***', 'tasks', 'run', 'spotify_recommender_dag_v3', 'get_dataset', 'scheduled__2024-12-08T00:00:00+00:00', '--job-id', '174', '--raw', '--subdir', 'DAGS_FOLDER/music_process.py', '--cfg-path', '/tmp/tmpeu3qfz4z']
[2024-12-14T16:31:17.984+0000] {standard_task_runner.py:88} INFO - Job 174: Subtask get_dataset
[2024-12-14T16:31:18.011+0000] {task_command.py:423} INFO - Running <TaskInstance: spotify_recommender_dag_v3.get_dataset scheduled__2024-12-08T00:00:00+00:00 [running]> on host 48d6c33eecc1
[2024-12-14T16:31:18.060+0000] {taskinstance.py:2480} INFO - Exporting env vars: AIRFLOW_CTX_DAG_OWNER='Mart√≠n Horn' AIRFLOW_CTX_DAG_ID='spotify_recommender_dag_v3' AIRFLOW_CTX_TASK_ID='get_dataset' AIRFLOW_CTX_EXECUTION_DATE='2024-12-08T00:00:00+00:00' AIRFLOW_CTX_TRY_NUMBER='1' AIRFLOW_CTX_DAG_RUN_ID='scheduled__2024-12-08T00:00:00+00:00'
[2024-12-14T16:31:18.061+0000] {process_utils.py:182} INFO - Executing cmd: /usr/local/bin/python -m virtualenv /tmp/venv8z01wi9_ --system-site-packages --python=python
[2024-12-14T16:31:18.064+0000] {process_utils.py:186} INFO - Output:
[2024-12-14T16:31:18.471+0000] {local_task_job_runner.py:121} ERROR - Received SIGTERM. Terminating subprocesses
[2024-12-14T16:31:18.473+0000] {process_utils.py:131} INFO - Sending 15 to group 253. PIDs of all processes in the group: [259, 253]
[2024-12-14T16:31:18.474+0000] {process_utils.py:86} INFO - Sending the signal 15 to group 253
[2024-12-14T16:31:18.475+0000] {taskinstance.py:2450} ERROR - Received SIGTERM. Terminating subprocesses.
[2024-12-14T16:31:18.497+0000] {taskinstance.py:2698} ERROR - Task failed with exception
Traceback (most recent call last):
  File "/home/airflow/.local/lib/python3.8/site-packages/airflow/models/taskinstance.py", line 433, in _execute_task
    result = execute_callable(context=context, **execute_callable_kwargs)
  File "/home/airflow/.local/lib/python3.8/site-packages/airflow/decorators/base.py", line 241, in execute
    return_value = super().execute(context)
  File "/home/airflow/.local/lib/python3.8/site-packages/airflow/operators/python.py", line 400, in execute
    return super().execute(context=serializable_context)
  File "/home/airflow/.local/lib/python3.8/site-packages/airflow/operators/python.py", line 199, in execute
    return_value = self.execute_callable()
  File "/home/airflow/.local/lib/python3.8/site-packages/airflow/operators/python.py", line 714, in execute_callable
    self._prepare_venv(tmp_path)
  File "/home/airflow/.local/lib/python3.8/site-packages/airflow/operators/python.py", line 626, in _prepare_venv
    prepare_virtualenv(
  File "/home/airflow/.local/lib/python3.8/site-packages/airflow/utils/python_virtualenv.py", line 104, in prepare_virtualenv
    execute_in_subprocess(virtualenv_cmd)
  File "/home/airflow/.local/lib/python3.8/site-packages/airflow/utils/process_utils.py", line 171, in execute_in_subprocess
    execute_in_subprocess_with_kwargs(cmd, cwd=cwd)
  File "/home/airflow/.local/lib/python3.8/site-packages/airflow/utils/process_utils.py", line 189, in execute_in_subprocess_with_kwargs
    for line in iter(proc.stdout.readline, b""):
  File "/home/airflow/.local/lib/python3.8/site-packages/airflow/models/taskinstance.py", line 2452, in signal_handler
    raise AirflowException("Task received SIGTERM signal")
airflow.exceptions.AirflowException: Task received SIGTERM signal
[2024-12-14T16:31:18.499+0000] {taskinstance.py:1138} INFO - Marking task as UP_FOR_RETRY. dag_id=spotify_recommender_dag_v3, task_id=get_dataset, execution_date=20241208T000000, start_date=20241214T163117, end_date=20241214T163118
[2024-12-14T16:31:18.508+0000] {standard_task_runner.py:107} ERROR - Failed to execute job 174 for task get_dataset (Task received SIGTERM signal; 253)
[2024-12-14T16:31:18.527+0000] {process_utils.py:79} INFO - Process psutil.Process(pid=253, status='terminated', exitcode=1, started='16:31:17') (253) terminated with exit code 1
[2024-12-14T16:31:18.527+0000] {process_utils.py:79} INFO - Process psutil.Process(pid=259, status='terminated', started='16:31:17') (259) terminated with exit code None
[2024-12-14T16:31:18.528+0000] {local_task_job_runner.py:234} INFO - Task exited with return code 143
[2024-12-14T16:31:18.543+0000] {taskinstance.py:3280} INFO - 0 downstream tasks scheduled from follow-on schedule check
